Workbook

Sheet Profile
A1: Buwiz Books: tax profile and category selection
A2: Choose a legal filer and mark relevant forms in both panels. Yellow cells are editable.
A3: This is a design selector, not a determination of legal filing obligations.
A5: Profile attribute | B5: Meaning | C5: Value | E5: Additional forms | F5: Purpose | G5: Selected
A6: Filer type | B6: Legal form | C6: Individual | E6: 1701Q | F6: Individual quarterly income tax | G6: Yes
A7: 2551Q selected | B7: Quarterly percentage tax | C7: Yes | E7: 1702 group | F7: Corporate / partnership income tax | G7: No
A8: 1601-C selected | B8: Employer compensation withholding | C8: Yes | E8: 2550Q | F8: VAT | G8: No
A9: 1701-MS selected | B9: Eligible micro / small annual individual return | C9: Yes | E9: 0619-E / 1601-EQ | F9: Supplier expanded withholding | G9: No
A10: Income tax regime | B10: For the annual return | C10: Graduated | E10: 1701 / 1701A | F10: Other individual annual return | G10: No
A11: Deduction method | B11: When graduated rates apply | C11: OSD
A12: Filer earns compensation | B12: Owner/taxpayer salary, not employee payroll | C12: No | E12: These extra forms suggest categories only. Their detailed form-field dictionaries are not yet included.
A13: Taxable year | B13: Reference only; the worked example is fixed | C13: 2026 | E13: 1702 group = 1702Q and the applicable 1702 annual return; confirm exact obligations.
A14: Quarter example | B14: Reference only; the worked example is fixed | C14: 3
A15: Month example | B15: Reference only; the worked example is fixed | C15: 9
A17: Profile review
A18: =IF(AND(C9="Yes",OR(C6="Corporation",C6="Partnership")),"Review: 1701-MS is an individual/fiduciary form, not a corporate return.","Entity/form check: review eligibility against the form instructions.")
A19: =IF(AND(C7="Yes",C10="8%"),"Review: valid 8% generally replaces Section 116; transition or other percentage taxes can still matter.","Review: verify COR tax types, registration, tax elections, period and activity.")
A20: =IF(AND(C10="8%",OR(C6="Corporation",C6="Partnership")),"Review: the 8% option is not a corporate / ordinary partnership income-tax regime.",IF(AND(G7="Yes",C6="Individual"),"Review: 1702 forms generally apply to non-individual filers.","Profile choices do not establish legal eligibility or calculate an obligation."))
A21: =IF(AND(C9="Yes",G6="No"),"Review whether 1701Q and other COR-based obligations also apply.","Review the entire obligation set, including certificates and required schedules.")
A22: How to use
A23: 1. Select the legal filer and forms in columns C and G. The Category catalog highlights the matching category candidates.
A24: 2. Filter Category catalog by Suggested / Core, and inspect Category field rules for the exact data and conditions.
A25: 3. Read all three numbered field dictionaries. Each field states whether it comes from a profile, ledger, payroll, certificate, calculation or human review.
A26: 4. Worked example demonstrates separate quarterly, monthly and annual sources. Its fictional data is independent of the profile selector.
A27: 5. COR tax types are a starting point. Elections, activities, transactions, legal entity, dates and other BIR records can add or change obligations.
A28: 6. Exact field coverage is limited to 2551Q Jan 2018, 1601-C Jan 2018, and 1701-MS Aug 2024. Other forms are cataloged as pending.
A29: 7. A selected 1601-C means the filer is an employer. It does not mean the owner earns compensation or loses the pure-business 8% reduction.
A31: Added review checks (correction 13; (c) and (e) only)
A32: =IF(AND(C10="8%",C12="Yes"),"Review: mixed earners get no 250,000 reduction on the 8% base (RMO 23-2018; verify s2 #75).","No mixed-earner 8% reduction issue flagged by this check.")
A33: =IF(AND(C10="8%",C7="Yes"),"Open discrepancy: an 8% year with 2551Q selected. Books blocks 2551Q; buwiz-oss requires NIL PT010; RMO 23-2018 says not required (verify s2 #73, #84). Do not file either way until RR 8-2018 is read.","No 8% and 2551Q conflict flagged.")

Sheet Category catalog
A1: Category catalog
A2: Filter the “Selection” column after changing Profile. Existing keys and numbers are copied from the pinned Buwiz preset.
A3: Core accounting categories remain useful even when no tax form directly needs them. Proposed keys have no account number.
A5: Category key | B5: Display name | C5: Account type | D5: Account no. | E5: Origin | F5: Activation rule | G5: Selection | H5: Purpose | I5: Checks / tax dimensions
A6: bank_accounts | B6: Bank Accounts | C6: asset | D6: 11000 | E6: Existing base | F6: Always | G6: =IF(F6="Always","CORE",IF(OR(AND(F6="INDIVIDUAL",Profile!$C$6="Individual"),AND(F6="PT",Profile!$C$7="Yes"),AND(F6="PAYROLL",Profile!$C$8="Yes"),AND(F6="IT",OR(Profile!$C$9="Yes",Profile!$G$6="Yes",Profile!$G$7="Yes",Profile!$G$10="Yes")),AND(F6="IT_OR_PAYROLL",OR(Profile!$C$8="Yes",OR(Profile!$C$9="Yes",Profile!$G$6="Yes",Profile!$G$7="Yes",Profile!$G$10="Yes"))),AND(F6="VAT",Profile!$G$8="Yes"),AND(F6="EWT",Profile!$G$9="Yes")),"SUGGESTED","OPTIONAL")) | H6: Cash and bank movements; reconcile | I6: No direct sales inference
A7: accounts_receivable_gross | B7: Accounts Receivable - Gross | C7: asset | D7: 12010 | E7: Existing base | F7: Always | G7: =IF(F7="Always","CORE",IF(OR(AND(F7="INDIVIDUAL",Profile!$C$6="Individual"),AND(F7="PT",Profile!$C$7="Yes"),AND(F7="PAYROLL",Profile!$C$8="Yes"),AND(F7="IT",OR(Profile!$C$9="Yes",Profile!$G$6="Yes",Profile!$G$7="Yes",Profile!$G$10="Yes")),AND(F7="IT_OR_PAYROLL",OR(Profile!$C$8="Yes",OR(Profile!$C$9="Yes",Profile!$G$6="Yes",Profile!$G$7="Yes",Profile!$G$10="Yes"))),AND(F7="VAT",Profile!$G$8="Yes"),AND(F7="EWT",Profile!$G$9="Yes")),"SUGGESTED","OPTIONAL")) | H7: Outstanding customer invoices | I7: Sales occur separately; do not use collections as revenue
A8: inventory | B8: Inventory | C8: asset | D8: 13500 | E8: Existing base | F8: Always | G8: =IF(F8="Always","CORE",IF(OR(AND(F8="INDIVIDUAL",Profile!$C$6="Individual"),AND(F8="PT",Profile!$C$7="Yes"),AND(F8="PAYROLL",Profile!$C$8="Yes"),AND(F8="IT",OR(Profile!$C$9="Yes",Profile!$G$6="Yes",Profile!$G$7="Yes",Profile!$G$10="Yes")),AND(F8="IT_OR_PAYROLL",OR(Profile!$C$8="Yes",OR(Profile!$C$9="Yes",Profile!$G$6="Yes",Profile!$G$7="Yes",Profile!$G$10="Yes"))),AND(F8="VAT",Profile!$G$8="Yes"),AND(F8="EWT",Profile!$G$9="Yes")),"SUGGESTED","OPTIONAL")) | H8: Stock held for sale | I8: Use cost of goods sold when goods leave inventory
A9: prepaid_expenses | B9: Prepaid Expenses | C9: asset | D9: 13000 | E9: Existing base | F9: Always | G9: =IF(F9="Always","CORE",IF(OR(AND(F9="INDIVIDUAL",Profile!$C$6="Individual"),AND(F9="PT",Profile!$C$7="Yes"),AND(F9="PAYROLL",Profile!$C$8="Yes"),AND(F9="IT",OR(Profile!$C$9="Yes",Profile!$G$6="Yes",Profile!$G$7="Yes",Profile!$G$10="Yes")),AND(F9="IT_OR_PAYROLL",OR(Profile!$C$8="Yes",OR(Profile!$C$9="Yes",Profile!$G$6="Yes",Profile!$G$7="Yes",Profile!$G$10="Yes"))),AND(F9="VAT",Profile!$G$8="Yes"),AND(F9="EWT",Profile!$G$9="Yes")),"SUGGESTED","OPTIONAL")) | H9: Payments for future benefit | I9: Recognize allowable expense at the proper time
A10: computer_assets | B10: Computer Assets | C10: asset | D10: 16100 | E10: Existing base | F10: Always | G10: =IF(F10="Always","CORE",IF(OR(AND(F10="INDIVIDUAL",Profile!$C$6="Individual"),AND(F10="PT",Profile!$C$7="Yes"),AND(F10="PAYROLL",Profile!$C$8="Yes"),AND(F10="IT",OR(Profile!$C$9="Yes",Profile!$G$6="Yes",Profile!$G$7="Yes",Profile!$G$10="Yes")),AND(F10="IT_OR_PAYROLL",OR(Profile!$C$8="Yes",OR(Profile!$C$9="Yes",Profile!$G$6="Yes",Profile!$G$7="Yes",Profile!$G$10="Yes"))),AND(F10="VAT",Profile!$G$8="Yes"),AND(F10="EWT",Profile!$G$9="Yes")),"SUGGESTED","OPTIONAL")) | H10: Capital equipment | I10: Depreciation / tax adjustments rather than automatic full deduction
A11: accounts_payable | B11: Accounts Payable | C11: liability | D11: 21000 | E11: Existing base | F11: Always | G11: =IF(F11="Always","CORE",IF(OR(AND(F11="INDIVIDUAL",Profile!$C$6="Individual"),AND(F11="PT",Profile!$C$7="Yes"),AND(F11="PAYROLL",Profile!$C$8="Yes"),AND(F11="IT",OR(Profile!$C$9="Yes",Profile!$G$6="Yes",Profile!$G$7="Yes",Profile!$G$10="Yes")),AND(F11="IT_OR_PAYROLL",OR(Profile!$C$8="Yes",OR(Profile!$C$9="Yes",Profile!$G$6="Yes",Profile!$G$7="Yes",Profile!$G$10="Yes"))),AND(F11="VAT",Profile!$G$8="Yes"),AND(F11="EWT",Profile!$G$9="Yes")),"SUGGESTED","OPTIONAL")) | H11: Supplier liability | I11: Track bill, withholding and payment separately
A12: owners_equity | B12: Owners Equity | C12: equity | D12: 32000 | E12: Existing base | F12: Always | G12: =IF(F12="Always","CORE",IF(OR(AND(F12="INDIVIDUAL",Profile!$C$6="Individual"),AND(F12="PT",Profile!$C$7="Yes"),AND(F12="PAYROLL",Profile!$C$8="Yes"),AND(F12="IT",OR(Profile!$C$9="Yes",Profile!$G$6="Yes",Profile!$G$7="Yes",Profile!$G$10="Yes")),AND(F12="IT_OR_PAYROLL",OR(Profile!$C$8="Yes",OR(Profile!$C$9="Yes",Profile!$G$6="Yes",Profile!$G$7="Yes",Profile!$G$10="Yes"))),AND(F12="VAT",Profile!$G$8="Yes"),AND(F12="EWT",Profile!$G$9="Yes")),"SUGGESTED","OPTIONAL")) | H12: Owner capital | I12: Capital is not sales
A13: owner_drawings | B13: Owner Drawings | C13: equity | E13: Proposed | F13: INDIVIDUAL | G13: =IF(F13="Always","CORE",IF(OR(AND(F13="INDIVIDUAL",Profile!$C$6="Individual"),AND(F13="PT",Profile!$C$7="Yes"),AND(F13="PAYROLL",Profile!$C$8="Yes"),AND(F13="IT",OR(Profile!$C$9="Yes",Profile!$G$6="Yes",Profile!$G$7="Yes",Profile!$G$10="Yes")),AND(F13="IT_OR_PAYROLL",OR(Profile!$C$8="Yes",OR(Profile!$C$9="Yes",Profile!$G$6="Yes",Profile!$G$7="Yes",Profile!$G$10="Yes"))),AND(F13="VAT",Profile!$G$8="Yes"),AND(F13="EWT",Profile!$G$9="Yes")),"SUGGESTED","OPTIONAL")) | H13: Owner withdrawals in a sole proprietorship | I13: Not a corporate salary or dividend; no frozen number assigned
A14: loan_payable | B14: Loans Payable | C14: liability | E14: Proposed | F14: Always | G14: =IF(F14="Always","CORE",IF(OR(AND(F14="INDIVIDUAL",Profile!$C$6="Individual"),AND(F14="PT",Profile!$C$7="Yes"),AND(F14="PAYROLL",Profile!$C$8="Yes"),AND(F14="IT",OR(Profile!$C$9="Yes",Profile!$G$6="Yes",Profile!$G$7="Yes",Profile!$G$10="Yes")),AND(F14="IT_OR_PAYROLL",OR(Profile!$C$8="Yes",OR(Profile!$C$9="Yes",Profile!$G$6="Yes",Profile!$G$7="Yes",Profile!$G$10="Yes"))),AND(F14="VAT",Profile!$G$8="Yes"),AND(F14="EWT",Profile!$G$9="Yes")),"SUGGESTED","OPTIONAL")) | H14: Financing principal | I14: Loan proceeds are not business sales
A15: sales_revenue | B15: Sales Revenue | C15: revenue | D15: 41000 | E15: Existing base | F15: Always | G15: =IF(F15="Always","CORE",IF(OR(AND(F15="INDIVIDUAL",Profile!$C$6="Individual"),AND(F15="PT",Profile!$C$7="Yes"),AND(F15="PAYROLL",Profile!$C$8="Yes"),AND(F15="IT",OR(Profile!$C$9="Yes",Profile!$G$6="Yes",Profile!$G$7="Yes",Profile!$G$10="Yes")),AND(F15="IT_OR_PAYROLL",OR(Profile!$C$8="Yes",OR(Profile!$C$9="Yes",Profile!$G$6="Yes",Profile!$G$7="Yes",Profile!$G$10="Yes"))),AND(F15="VAT",Profile!$G$8="Yes"),AND(F15="EWT",Profile!$G$9="Yes")),"SUGGESTED","OPTIONAL")) | H15: Goods / service sales | I15: Tax attributes determine form treatment
A16: subscription_revenue | B16: Subscription Revenue | C16: revenue | D16: 42000 | E16: Existing base | F16: Always | G16: =IF(F16="Always","CORE",IF(OR(AND(F16="INDIVIDUAL",Profile!$C$6="Individual"),AND(F16="PT",Profile!$C$7="Yes"),AND(F16="PAYROLL",Profile!$C$8="Yes"),AND(F16="IT",OR(Profile!$C$9="Yes",Profile!$G$6="Yes",Profile!$G$7="Yes",Profile!$G$10="Yes")),AND(F16="IT_OR_PAYROLL",OR(Profile!$C$8="Yes",OR(Profile!$C$9="Yes",Profile!$G$6="Yes",Profile!$G$7="Yes",Profile!$G$10="Yes"))),AND(F16="VAT",Profile!$G$8="Yes"),AND(F16="EWT",Profile!$G$9="Yes")),"SUGGESTED","OPTIONAL")) | H16: Subscription sales | I16: Tax attributes determine form treatment
A17: transaction_revenue | B17: Transaction Revenue | C17: revenue | D17: 43000 | E17: Existing base | F17: Always | G17: =IF(F17="Always","CORE",IF(OR(AND(F17="INDIVIDUAL",Profile!$C$6="Individual"),AND(F17="PT",Profile!$C$7="Yes"),AND(F17="PAYROLL",Profile!$C$8="Yes"),AND(F17="IT",OR(Profile!$C$9="Yes",Profile!$G$6="Yes",Profile!$G$7="Yes",Profile!$G$10="Yes")),AND(F17="IT_OR_PAYROLL",OR(Profile!$C$8="Yes",OR(Profile!$C$9="Yes",Profile!$G$6="Yes",Profile!$G$7="Yes",Profile!$G$10="Yes"))),AND(F17="VAT",Profile!$G$8="Yes"),AND(F17="EWT",Profile!$G$9="Yes")),"SUGGESTED","OPTIONAL")) | H17: Transaction fees and other sales | I17: Tax attributes determine form treatment
A18: refunds_and_discounts | B18: Refunds & Discounts | C18: revenue | D18: 49000 | E18: Existing base | F18: Always | G18: =IF(F18="Always","CORE",IF(OR(AND(F18="INDIVIDUAL",Profile!$C$6="Individual"),AND(F18="PT",Profile!$C$7="Yes"),AND(F18="PAYROLL",Profile!$C$8="Yes"),AND(F18="IT",OR(Profile!$C$9="Yes",Profile!$G$6="Yes",Profile!$G$7="Yes",Profile!$G$10="Yes")),AND(F18="IT_OR_PAYROLL",OR(Profile!$C$8="Yes",OR(Profile!$C$9="Yes",Profile!$G$6="Yes",Profile!$G$7="Yes",Profile!$G$10="Yes"))),AND(F18="VAT",Profile!$G$8="Yes"),AND(F18="EWT",Profile!$G$9="Yes")),"SUGGESTED","OPTIONAL")) | H18: Sales returns, allowances and discounts | I18: Link to original sale and apply valid tax treatment [Books: revenue + subtype refunds_discounts (correction 19)]
A19: other_non_operating_income | B19: Other Non-Operating Income | C19: other_income | E19: Proposed | F19: IT | G19: =IF(F19="Always","CORE",IF(OR(AND(F19="INDIVIDUAL",Profile!$C$6="Individual"),AND(F19="PT",Profile!$C$7="Yes"),AND(F19="PAYROLL",Profile!$C$8="Yes"),AND(F19="IT",OR(Profile!$C$9="Yes",Profile!$G$6="Yes",Profile!$G$7="Yes",Profile!$G$10="Yes")),AND(F19="IT_OR_PAYROLL",OR(Profile!$C$8="Yes",OR(Profile!$C$9="Yes",Profile!$G$6="Yes",Profile!$G$7="Yes",Profile!$G$10="Yes"))),AND(F19="VAT",Profile!$G$8="Yes"),AND(F19="EWT",Profile!$G$9="Yes")),"SUGGESTED","OPTIONAL")) | H19: Separate eligible non-operating income from sales | I19: Exclude income already subject to final tax when applicable
A20: interest_income | B20: Interest Income | C20: other_income | D20: 81000 | E20: Existing base | F20: IT | G20: =IF(F20="Always","CORE",IF(OR(AND(F20="INDIVIDUAL",Profile!$C$6="Individual"),AND(F20="PT",Profile!$C$7="Yes"),AND(F20="PAYROLL",Profile!$C$8="Yes"),AND(F20="IT",OR(Profile!$C$9="Yes",Profile!$G$6="Yes",Profile!$G$7="Yes",Profile!$G$10="Yes")),AND(F20="IT_OR_PAYROLL",OR(Profile!$C$8="Yes",OR(Profile!$C$9="Yes",Profile!$G$6="Yes",Profile!$G$7="Yes",Profile!$G$10="Yes"))),AND(F20="VAT",Profile!$G$8="Yes"),AND(F20="EWT",Profile!$G$9="Yes")),"SUGGESTED","OPTIONAL")) | H20: Interest income | I20: Tax attribute must distinguish final-taxed vs income included in return
A21: cost_of_goods_sold | B21: Cost of Goods Sold | C21: cost_of_revenue | D21: 51000 | E21: Existing base | F21: Always | G21: =IF(F21="Always","CORE",IF(OR(AND(F21="INDIVIDUAL",Profile!$C$6="Individual"),AND(F21="PT",Profile!$C$7="Yes"),AND(F21="PAYROLL",Profile!$C$8="Yes"),AND(F21="IT",OR(Profile!$C$9="Yes",Profile!$G$6="Yes",Profile!$G$7="Yes",Profile!$G$10="Yes")),AND(F21="IT_OR_PAYROLL",OR(Profile!$C$8="Yes",OR(Profile!$C$9="Yes",Profile!$G$6="Yes",Profile!$G$7="Yes",Profile!$G$10="Yes"))),AND(F21="VAT",Profile!$G$8="Yes"),AND(F21="EWT",Profile!$G$9="Yes")),"SUGGESTED","OPTIONAL")) | H21: Cost of inventory sold | I21: 1701-MS IV.8 only when itemized and eligible
A22: direct_service_cost | B22: Direct Cost of Services | C22: cost_of_revenue | E22: Proposed | F22: IT | G22: =IF(F22="Always","CORE",IF(OR(AND(F22="INDIVIDUAL",Profile!$C$6="Individual"),AND(F22="PT",Profile!$C$7="Yes"),AND(F22="PAYROLL",Profile!$C$8="Yes"),AND(F22="IT",OR(Profile!$C$9="Yes",Profile!$G$6="Yes",Profile!$G$7="Yes",Profile!$G$10="Yes")),AND(F22="IT_OR_PAYROLL",OR(Profile!$C$8="Yes",OR(Profile!$C$9="Yes",Profile!$G$6="Yes",Profile!$G$7="Yes",Profile!$G$10="Yes"))),AND(F22="VAT",Profile!$G$8="Yes"),AND(F22="EWT",Profile!$G$9="Yes")),"SUGGESTED","OPTIONAL")) | H22: Direct cost of services | I22: Potential IV.8 itemized cost; no frozen number assigned
A23: salaries | B23: Salaries | C23: expense | D23: 61100 | E23: Existing base | F23: IT_OR_PAYROLL | G23: =IF(F23="Always","CORE",IF(OR(AND(F23="INDIVIDUAL",Profile!$C$6="Individual"),AND(F23="PT",Profile!$C$7="Yes"),AND(F23="PAYROLL",Profile!$C$8="Yes"),AND(F23="IT",OR(Profile!$C$9="Yes",Profile!$G$6="Yes",Profile!$G$7="Yes",Profile!$G$10="Yes")),AND(F23="IT_OR_PAYROLL",OR(Profile!$C$8="Yes",OR(Profile!$C$9="Yes",Profile!$G$6="Yes",Profile!$G$7="Yes",Profile!$G$10="Yes"))),AND(F23="VAT",Profile!$G$8="Yes"),AND(F23="EWT",Profile!$G$9="Yes")),"SUGGESTED","OPTIONAL")) | H23: Employee gross compensation expense | I23: 1601-C reads employee detail; reconcile ledger
A24: employee_benefits | B24: Employee Benefits | C24: expense | D24: 61400 | E24: Existing base | F24: IT_OR_PAYROLL | G24: =IF(F24="Always","CORE",IF(OR(AND(F24="INDIVIDUAL",Profile!$C$6="Individual"),AND(F24="PT",Profile!$C$7="Yes"),AND(F24="PAYROLL",Profile!$C$8="Yes"),AND(F24="IT",OR(Profile!$C$9="Yes",Profile!$G$6="Yes",Profile!$G$7="Yes",Profile!$G$10="Yes")),AND(F24="IT_OR_PAYROLL",OR(Profile!$C$8="Yes",OR(Profile!$C$9="Yes",Profile!$G$6="Yes",Profile!$G$7="Yes",Profile!$G$10="Yes"))),AND(F24="VAT",Profile!$G$8="Yes"),AND(F24="EWT",Profile!$G$9="Yes")),"SUGGESTED","OPTIONAL")) | H24: Employer-paid employee benefits | I24: A benefit may be taxable, exempt or partially exempt
A25: retirement_contributions | B25: Retirement Contributions | C25: expense | D25: 61500 | E25: Existing base | F25: IT_OR_PAYROLL | G25: =IF(F25="Always","CORE",IF(OR(AND(F25="INDIVIDUAL",Profile!$C$6="Individual"),AND(F25="PT",Profile!$C$7="Yes"),AND(F25="PAYROLL",Profile!$C$8="Yes"),AND(F25="IT",OR(Profile!$C$9="Yes",Profile!$G$6="Yes",Profile!$G$7="Yes",Profile!$G$10="Yes")),AND(F25="IT_OR_PAYROLL",OR(Profile!$C$8="Yes",OR(Profile!$C$9="Yes",Profile!$G$6="Yes",Profile!$G$7="Yes",Profile!$G$10="Yes"))),AND(F25="VAT",Profile!$G$8="Yes"),AND(F25="EWT",Profile!$G$9="Yes")),"SUGGESTED","OPTIONAL")) | H25: Employer contributions | I25: Do not treat employee-share deductions as employer expense
A26: employer_payroll_taxes | B26: Employer Payroll Taxes | C26: expense | D26: 61600 | E26: Existing base | F26: IT_OR_PAYROLL | G26: =IF(F26="Always","CORE",IF(OR(AND(F26="INDIVIDUAL",Profile!$C$6="Individual"),AND(F26="PT",Profile!$C$7="Yes"),AND(F26="PAYROLL",Profile!$C$8="Yes"),AND(F26="IT",OR(Profile!$C$9="Yes",Profile!$G$6="Yes",Profile!$G$7="Yes",Profile!$G$10="Yes")),AND(F26="IT_OR_PAYROLL",OR(Profile!$C$8="Yes",OR(Profile!$C$9="Yes",Profile!$G$6="Yes",Profile!$G$7="Yes",Profile!$G$10="Yes"))),AND(F26="VAT",Profile!$G$8="Yes"),AND(F26="EWT",Profile!$G$9="Yes")),"SUGGESTED","OPTIONAL")) | H26: Employer portion when categorized here | I26: Use distinct employee and employer shares
A27: payroll_processing_fees | B27: Payroll Processing Fees | C27: expense | D27: 61700 | E27: Existing base | F27: IT_OR_PAYROLL | G27: =IF(F27="Always","CORE",IF(OR(AND(F27="INDIVIDUAL",Profile!$C$6="Individual"),AND(F27="PT",Profile!$C$7="Yes"),AND(F27="PAYROLL",Profile!$C$8="Yes"),AND(F27="IT",OR(Profile!$C$9="Yes",Profile!$G$6="Yes",Profile!$G$7="Yes",Profile!$G$10="Yes")),AND(F27="IT_OR_PAYROLL",OR(Profile!$C$8="Yes",OR(Profile!$C$9="Yes",Profile!$G$6="Yes",Profile!$G$7="Yes",Profile!$G$10="Yes"))),AND(F27="VAT",Profile!$G$8="Yes"),AND(F27="EWT",Profile!$G$9="Yes")),"SUGGESTED","OPTIONAL")) | H27: Payroll-service fees | I27: Potential itemized deduction with support
A28: payment_processing_fees | B28: Payment Processing Fees | C28: cost_of_revenue | D28: 53000 | E28: Existing base | F28: IT | G28: =IF(F28="Always","CORE",IF(OR(AND(F28="INDIVIDUAL",Profile!$C$6="Individual"),AND(F28="PT",Profile!$C$7="Yes"),AND(F28="PAYROLL",Profile!$C$8="Yes"),AND(F28="IT",OR(Profile!$C$9="Yes",Profile!$G$6="Yes",Profile!$G$7="Yes",Profile!$G$10="Yes")),AND(F28="IT_OR_PAYROLL",OR(Profile!$C$8="Yes",OR(Profile!$C$9="Yes",Profile!$G$6="Yes",Profile!$G$7="Yes",Profile!$G$10="Yes"))),AND(F28="VAT",Profile!$G$8="Yes"),AND(F28="EWT",Profile!$G$9="Yes")),"SUGGESTED","OPTIONAL")) | H28: Payment processor fees | I28: Income-tax placement requires accounting/tax review
A29: hosting_fees | B29: Hosting Fees | C29: cost_of_revenue | D29: 54000 | E29: Existing base | F29: IT | G29: =IF(F29="Always","CORE",IF(OR(AND(F29="INDIVIDUAL",Profile!$C$6="Individual"),AND(F29="PT",Profile!$C$7="Yes"),AND(F29="PAYROLL",Profile!$C$8="Yes"),AND(F29="IT",OR(Profile!$C$9="Yes",Profile!$G$6="Yes",Profile!$G$7="Yes",Profile!$G$10="Yes")),AND(F29="IT_OR_PAYROLL",OR(Profile!$C$8="Yes",OR(Profile!$C$9="Yes",Profile!$G$6="Yes",Profile!$G$7="Yes",Profile!$G$10="Yes"))),AND(F29="VAT",Profile!$G$8="Yes"),AND(F29="EWT",Profile!$G$9="Yes")),"SUGGESTED","OPTIONAL")) | H29: Hosting directly categorized as cost | I29: Income-tax placement requires review
A30: consultants_and_contractors | B30: Consultants and Contractors | C30: expense | D30: 63100 | E30: Existing base | F30: IT | G30: =IF(F30="Always","CORE",IF(OR(AND(F30="INDIVIDUAL",Profile!$C$6="Individual"),AND(F30="PT",Profile!$C$7="Yes"),AND(F30="PAYROLL",Profile!$C$8="Yes"),AND(F30="IT",OR(Profile!$C$9="Yes",Profile!$G$6="Yes",Profile!$G$7="Yes",Profile!$G$10="Yes")),AND(F30="IT_OR_PAYROLL",OR(Profile!$C$8="Yes",OR(Profile!$C$9="Yes",Profile!$G$6="Yes",Profile!$G$7="Yes",Profile!$G$10="Yes"))),AND(F30="VAT",Profile!$G$8="Yes"),AND(F30="EWT",Profile!$G$9="Yes")),"SUGGESTED","OPTIONAL")) | H30: Independent contractor fees | I30: Potential supplier EWT is separate
A31: legal | B31: Legal | C31: expense | D31: 63200 | E31: Existing base | F31: IT | G31: =IF(F31="Always","CORE",IF(OR(AND(F31="INDIVIDUAL",Profile!$C$6="Individual"),AND(F31="PT",Profile!$C$7="Yes"),AND(F31="PAYROLL",Profile!$C$8="Yes"),AND(F31="IT",OR(Profile!$C$9="Yes",Profile!$G$6="Yes",Profile!$G$7="Yes",Profile!$G$10="Yes")),AND(F31="IT_OR_PAYROLL",OR(Profile!$C$8="Yes",OR(Profile!$C$9="Yes",Profile!$G$6="Yes",Profile!$G$7="Yes",Profile!$G$10="Yes"))),AND(F31="VAT",Profile!$G$8="Yes"),AND(F31="EWT",Profile!$G$9="Yes")),"SUGGESTED","OPTIONAL")) | H31: Legal services | I31: Potential supplier EWT is separate
A32: tax_and_accounting | B32: Tax & Accounting | C32: expense | D32: 63300 | E32: Existing base | F32: IT | G32: =IF(F32="Always","CORE",IF(OR(AND(F32="INDIVIDUAL",Profile!$C$6="Individual"),AND(F32="PT",Profile!$C$7="Yes"),AND(F32="PAYROLL",Profile!$C$8="Yes"),AND(F32="IT",OR(Profile!$C$9="Yes",Profile!$G$6="Yes",Profile!$G$7="Yes",Profile!$G$10="Yes")),AND(F32="IT_OR_PAYROLL",OR(Profile!$C$8="Yes",OR(Profile!$C$9="Yes",Profile!$G$6="Yes",Profile!$G$7="Yes",Profile!$G$10="Yes"))),AND(F32="VAT",Profile!$G$8="Yes"),AND(F32="EWT",Profile!$G$9="Yes")),"SUGGESTED","OPTIONAL")) | H32: Accountancy and tax preparation | I32: Potential supplier EWT is separate
A33: advertising | B33: Advertising | C33: expense | D33: 64100 | E33: Existing base | F33: IT | G33: =IF(F33="Always","CORE",IF(OR(AND(F33="INDIVIDUAL",Profile!$C$6="Individual"),AND(F33="PT",Profile!$C$7="Yes"),AND(F33="PAYROLL",Profile!$C$8="Yes"),AND(F33="IT",OR(Profile!$C$9="Yes",Profile!$G$6="Yes",Profile!$G$7="Yes",Profile!$G$10="Yes")),AND(F33="IT_OR_PAYROLL",OR(Profile!$C$8="Yes",OR(Profile!$C$9="Yes",Profile!$G$6="Yes",Profile!$G$7="Yes",Profile!$G$10="Yes"))),AND(F33="VAT",Profile!$G$8="Yes"),AND(F33="EWT",Profile!$G$9="Yes")),"SUGGESTED","OPTIONAL")) | H33: Marketing spend | I33: Business purpose and invoice required
A34: business_applications_and_software | B34: Business Applications & Software | C34: expense | D34: 65000 | E34: Existing base | F34: IT | G34: =IF(F34="Always","CORE",IF(OR(AND(F34="INDIVIDUAL",Profile!$C$6="Individual"),AND(F34="PT",Profile!$C$7="Yes"),AND(F34="PAYROLL",Profile!$C$8="Yes"),AND(F34="IT",OR(Profile!$C$9="Yes",Profile!$G$6="Yes",Profile!$G$7="Yes",Profile!$G$10="Yes")),AND(F34="IT_OR_PAYROLL",OR(Profile!$C$8="Yes",OR(Profile!$C$9="Yes",Profile!$G$6="Yes",Profile!$G$7="Yes",Profile!$G$10="Yes"))),AND(F34="VAT",Profile!$G$8="Yes"),AND(F34="EWT",Profile!$G$9="Yes")),"SUGGESTED","OPTIONAL")) | H34: Software subscriptions | I34: Check service, tax, cross-border and capitalization facts
... A42: interest_expense | B42: Interest Expense | C42: other_expense | D42: 91000 | E42: Existing base | F42: IT | G42: =IF(F42="Always","CORE",IF(OR(AND(F42="INDIVIDUAL",Profile!$C$6="Individual"),AND(F42="PT",Profile!$C$7="Yes"),AND(F42="PAYROLL",Profile!$C$8="Yes"),AND(F42="IT",OR(Profile!$C$9="Yes",Profile!$G$6="Yes",Profile!$G$7="Yes",Profile!$G$10="Yes")),AND(F42="IT_OR_PAYROLL",OR(Profile!$C$8="Yes",OR(Profile!$C$9="Yes",Profile!$G$6="Yes",Profile!$G$7="Yes",Profile!$G$10="Yes"))),AND(F42="VAT",Profile!$G$8="Yes"),AND(F42="EWT",Profile!$G$9="Yes")),"SUGGESTED","OPTIONAL")) | H42: Business borrowing cost | I42: Apply restrictions; principal is not an expense
A43: depreciation_expense | B43: Depreciation Expense | C43: expense | E43: Proposed | F43: IT | G43: =IF(F43="Always","CORE",IF(OR(AND(F43="INDIVIDUAL",Profile!$C$6="Individual"),AND(F43="PT",Profile!$C$7="Yes"),AND(F43="PAYROLL",Profile!$C$8="Yes"),AND(F43="IT",OR(Profile!$C$9="Yes",Profile!$G$6="Yes",Profile!$G$7="Yes",Profile!$G$10="Yes")),AND(F43="IT_OR_PAYROLL",OR(Profile!$C$8="Yes",OR(Profile!$C$9="Yes",Profile!$G$6="Yes",Profile!$G$7="Yes",Profile!$G$10="Yes"))),AND(F43="VAT",Profile!$G$8="Yes"),AND(F43="EWT",Profile!$G$9="Yes")),"SUGGESTED","OPTIONAL")) | H43: Periodic fixed-asset cost | I43: Use fixed asset schedule and tax adjustment
A44: ph_cwt_receivable | B44: Creditable Withholding Tax Receivable | C44: asset | D44: 12600 | E44: Existing PH control | F44: IT | G44: =IF(F44="Always","CORE",IF(OR(AND(F44="INDIVIDUAL",Profile!$C$6="Individual"),AND(F44="PT",Profile!$C$7="Yes"),AND(F44="PAYROLL",Profile!$C$8="Yes"),AND(F44="IT",OR(Profile!$C$9="Yes",Profile!$G$6="Yes",Profile!$G$7="Yes",Profile!$G$10="Yes")),AND(F44="IT_OR_PAYROLL",OR(Profile!$C$8="Yes",OR(Profile!$C$9="Yes",Profile!$G$6="Yes",Profile!$G$7="Yes",Profile!$G$10="Yes"))),AND(F44="VAT",Profile!$G$8="Yes"),AND(F44="EWT",Profile!$G$9="Yes")),"SUGGESTED","OPTIONAL")) | H44: Income-tax withholding received | I44: Use income-tax 2307 amount by quarter
A45: pct_tax_credit_receivable | B45: Percentage Tax Withheld Receivable | C45: asset | E45: Proposed | F45: PT | G45: =IF(F45="Always","CORE",IF(OR(AND(F45="INDIVIDUAL",Profile!$C$6="Individual"),AND(F45="PT",Profile!$C$7="Yes"),AND(F45="PAYROLL",Profile!$C$8="Yes"),AND(F45="IT",OR(Profile!$C$9="Yes",Profile!$G$6="Yes",Profile!$G$7="Yes",Profile!$G$10="Yes")),AND(F45="IT_OR_PAYROLL",OR(Profile!$C$8="Yes",OR(Profile!$C$9="Yes",Profile!$G$6="Yes",Profile!$G$7="Yes",Profile!$G$10="Yes"))),AND(F45="VAT",Profile!$G$8="Yes"),AND(F45="EWT",Profile!$G$9="Yes")),"SUGGESTED","OPTIONAL")) | H45: Percentage tax withheld from the seller | I45: Optional separate control; distinguish from income-tax CWT
A46: ph_percentage_tax_payable | B46: Percentage Tax Payable | C46: liability | D46: 21800 | E46: Existing PH control | F46: PT | G46: =IF(F46="Always","CORE",IF(OR(AND(F46="INDIVIDUAL",Profile!$C$6="Individual"),AND(F46="PT",Profile!$C$7="Yes"),AND(F46="PAYROLL",Profile!$C$8="Yes"),AND(F46="IT",OR(Profile!$C$9="Yes",Profile!$G$6="Yes",Profile!$G$7="Yes",Profile!$G$10="Yes")),AND(F46="IT_OR_PAYROLL",OR(Profile!$C$8="Yes",OR(Profile!$C$9="Yes",Profile!$G$6="Yes",Profile!$G$7="Yes",Profile!$G$10="Yes"))),AND(F46="VAT",Profile!$G$8="Yes"),AND(F46="EWT",Profile!$G$9="Yes")),"SUGGESTED","OPTIONAL")) | H46: Accrued percentage tax | I46: Reconcile to 2551Q; not the taxable-sales base
A47: ph_percentage_tax_expense | B47: Percentage Tax Expense | C47: other_expense | D47: 94100 | E47: Existing PH control | F47: PT | G47: =IF(F47="Always","CORE",IF(OR(AND(F47="INDIVIDUAL",Profile!$C$6="Individual"),AND(F47="PT",Profile!$C$7="Yes"),AND(F47="PAYROLL",Profile!$C$8="Yes"),AND(F47="IT",OR(Profile!$C$9="Yes",Profile!$G$6="Yes",Profile!$G$7="Yes",Profile!$G$10="Yes")),AND(F47="IT_OR_PAYROLL",OR(Profile!$C$8="Yes",OR(Profile!$C$9="Yes",Profile!$G$6="Yes",Profile!$G$7="Yes",Profile!$G$10="Yes"))),AND(F47="VAT",Profile!$G$8="Yes"),AND(F47="EWT",Profile!$G$9="Yes")),"SUGGESTED","OPTIONAL")) | H47: Percentage tax cost | I47: Potential itemized tax deduction; check conditions
A48: income_tax_paid | B48: Income Tax Payments / Credits | C48: asset | E48: Proposed | F48: IT | G48: =IF(F48="Always","CORE",IF(OR(AND(F48="INDIVIDUAL",Profile!$C$6="Individual"),AND(F48="PT",Profile!$C$7="Yes"),AND(F48="PAYROLL",Profile!$C$8="Yes"),AND(F48="IT",OR(Profile!$C$9="Yes",Profile!$G$6="Yes",Profile!$G$7="Yes",Profile!$G$10="Yes")),AND(F48="IT_OR_PAYROLL",OR(Profile!$C$8="Yes",OR(Profile!$C$9="Yes",Profile!$G$6="Yes",Profile!$G$7="Yes",Profile!$G$10="Yes"))),AND(F48="VAT",Profile!$G$8="Yes"),AND(F48="EWT",Profile!$G$9="Yes")),"SUGGESTED","OPTIONAL")) | H48: Prior income-tax payments | I48: Retain return, period, amount and proof
...

Sheet Category field rules
A1: Category to form-field rules
A2: This is the many-to-many mapping layer. “Reconcile” rows are control checks, not instructions to sum the account into the field.
A3: Period, payer, tax type, eligibility and form version are part of every rule. Official sources S1–S4.
A5: Category key | B5: Form | C5: Target field | D5: Mapping method | E5: Period | F5: Required filter / dimension | G5: Review or exclusion
A6: sales_revenue | B6: 2551Q | C6: S1.1.base | D6: Aggregate tax-tagged revenue | E6: Quarter | F6: PT010 eligible sales, applicable recognition date | G6: Other ATCs require their own schedule row
A7: sales_revenue | B7: 1701-MS | C7: IV.5 | D7: Aggregate income-eligible gross sales | E7: Year | F7: Filer, non-final income, exclude VAT | G7: Use leaf accounts; do not also sum parent
A8: sales_revenue | B8: 1701-MS | C8: IV.19 | D8: Aggregate eligible net sales | E8: Year | F8: 8% pathway only; subtract eligible returns | G8: Do not use gross bank deposits
A9: subscription_revenue | B9: 2551Q | C9: S1.1.base | D9: Aggregate tax-tagged revenue | E9: Quarter | F9: PT010 eligible sales, applicable recognition date | G9: Other ATCs require their own schedule row
A10: subscription_revenue | B10: 1701-MS | C10: IV.5 | D10: Aggregate income-eligible gross sales | E10: Year | F10: Filer, non-final income, exclude VAT | G10: Use leaf accounts; do not also sum parent
A11: subscription_revenue | B11: 1701-MS | C11: IV.19 | D11: Aggregate eligible net sales | E11: Year | F11: 8% pathway only; subtract eligible returns | G11: Do not use gross bank deposits
A12: transaction_revenue | B12: 2551Q | C12: S1.1.base | D12: Aggregate tax-tagged revenue | E12: Quarter | F12: PT010 eligible sales, applicable recognition date | G12: Other ATCs require their own schedule row
A13: transaction_revenue | B13: 1701-MS | C13: IV.5 | D13: Aggregate income-eligible gross sales | E13: Year | F13: Filer, non-final income, exclude VAT | G13: Use leaf accounts; do not also sum parent
A14: transaction_revenue | B14: 1701-MS | C14: IV.19 | D14: Aggregate eligible net sales | E14: Year | F14: 8% pathway only; subtract eligible returns | G14: Do not use gross bank deposits
A15: refunds_and_discounts | B15: 2551Q | C15: S1.1.base | D15: Subtract eligible sales adjustments | E15: Quarter | F15: PT010 adjustment to covered sale | G15: Confirm recognition and credit note
A16: refunds_and_discounts | B16: 1701-MS | C16: IV.6 | D16: Sum eligible contra sales | E16: Year | F16: Graduated/special pathway | G16: Do not treat as unrelated expense
... A57: ph_percentage_tax_payable | B57: 2551Q | C57: II.14 | D57: Reconcile tax liability | E57: Quarter | F57: Posted percentage-tax assessment | G57: Return tax is computed from ATC base, not payable balance

Sheet 2551Q fields
A1: 2551Q field dictionary
A2: January 2018 (ENCS), 2 pages. Stable IDs include the section to prevent duplicated item numbers.
A3: Rows 1–6 of Schedule 1 and each payment column are expanded. Official source S1.
A5: Section | B5: Field ID | C5: BIR field | D5: Origin | E5: Source / data | F5: Rule or condition | G5: Grain | H5: Status
A6: Header | B6: H.1 | C6: Calendar or fiscal year | D6: Profile | E6: Fiscal-year configuration | F6: Calendar/fiscal selector | G6: Return | H6: Specified
A7: Header | B7: H.2 | C7: Year ended (MM/YYYY) | D7: Period | E7: Tax period end | F7: Do not infer solely from transaction date | G7: Return | H7: Specified
A8: Header | B8: H.3 | C8: Quarter | D8: Period | E8: Return period | F8: 1st / 2nd / 3rd / 4th | G8: Return | H8: Specified
A9: Header | B9: H.4 | C9: Amended return? | D9: Filing | E9: Return version | F9: Link original filing when Yes | G9: Return | H9: Specified
A10: Header | B10: H.5 | C10: Number of sheets attached | D10: Filing | E10: Attachment list | F10: Count the submitted sheets | G10: Return | H10: Specified
A11: I | B11: I.6 | C11: Taxpayer identification number | D11: Profile | E11: org_tax_profiles.tin + branchCode | F11: Validate taxpayer and branch | G11: Return | H11: Specified
A12: I | B12: I.7 | C12: RDO code | D12: Profile | E12: org_tax_profiles.rdoCode | F12: Use registered RDO | G12: Return | H12: Specified
A13: I | B13: I.8 | C13: Taxpayer name | D13: Profile | E13: registeredName | F13: Individual full name or entity registered name | G13: Return | H13: Specified
A14: I | B14: I.9 | C14: Registered address | D14: Profile | E14: Registered address / branch profile | F14: Use correct filing identity | G14: Return | H14: Specified
A15: I | B15: I.9A | C15: ZIP code | D15: Profile | E15: Registered address | F15: Text identifier, not a number | G15: Return | H15: Specified
A16: I | B16: I.10 | C16: Contact number | D16: Profile | E16: Contact data | F16: Not an accounting category | G16: Return | H16: Specified
... A77: III | B77: III.28.particular | C77: Other payment: particulars (Particular 28; key txtParticular28) | D77: Payment | E77: Payment evidence | F77: Record only if method 28 is used; unmapped in pinned schema (verify s4) | G77: Payment row | H77: Specified; added by correction 29

Sheet 1601-C fields
A1: 1601-C field dictionary
A2: January 2018 (ENCS). These are employer filings; a business owner’s salary is a different dataset.
A3: Employer contribution totals cannot replace the employee-share detail in item 19. Official source S2.
A5: Section | B5: Field ID | C5: BIR field | D5: Origin | E5: Source / data | F5: Rule or condition | G5: Grain | H5: Status
A6: Header | B6: H.1 | C6: For the month (MM/YYYY) | D6: Period | E6: Filing period | F6: Monthly | G6: Return | H6: Specified
A7: Header | B7: H.2 | C7: Amended return? | D7: Filing | E7: Return version | F7: Link original | G7: Return | H7: Specified
A8: Header | B8: H.3 | C8: Any taxes withheld? | D8: Payroll / filing | E8: Withholding detail | F8: Confirm zero payroll vs no withholding | G8: Return | H8: Specified
A9: Header | B9: H.4 | C9: Number of sheets attached | D9: Filing | E9: Attachment records | F9: Count submitted | G9: Return | H9: Specified
A10: Header | B10: H.5 | C10: ATC | D10: Reference | E10: WW010 | F10: Compensation withholding | G10: Return | H10: Specified
A11: I | B11: I.6 | C11: Taxpayer identification number | D11: Profile | E11: org_tax_profiles.tin + branchCode | F11: Employer / withholding agent | G11: Return | H11: Specified
A12: I | B12: I.7 | C12: RDO code | D12: Profile | E12: org_tax_profiles.rdoCode | F12: Employer registration | G12: Return | H12: Specified
A13: I | B13: I.8 | C13: Withholding agent name | D13: Profile | E13: registeredName | F13: Employer, not employee | G13: Return | H13: Specified
A14: I | B14: I.9 | C14: Registered address | D14: Profile | E14: Registered / branch address | F14: Employer filing identity | G14: Return | H14: Specified
A15: I | B15: I.9A | C15: ZIP code | D15: Profile | E15: Address data | F15: Text identifier | G15: Return | H15: Specified
A16: I | B16: I.10 | C16: Contact number | D16: Profile | E16: Contact data | F16: Not an account | G16: Return | H16: Specified
... A41: II | B41: II.34 | C41: Compromise | D41: Manual review | E41: Penalty assessment | F41: Not salary | G41: Return | H41: Specified
A42: II | B42: II.35 | C42: Total penalties | D42: Calculated | E42: II.32 + II.33 + II.34 | G42: Return | H42: Specified
A43: II | B43: II.36 | C43: Total amount still due / overremittance | D43: Calculated | E43: II.31 + II.35 | F43: Preserve sign | G43: Return | H43: Specified
A44: III | B44: III.37.bank | C44: Cash / bank debit: Drawee bank / agency | D44: Payment | E44: Payment evidence | F44: Record if method 37 is used | G44: Payment row | H44: Specified
A45: III | B45: III.37.number | C45: Cash / bank debit: Reference number | D45: Payment | E45: Payment evidence | F45: Record if method 37 is used | G45: Payment row | H45: Specified
A46: III | B46: III.37.date | C46: Cash / bank debit: Payment date | D46: Payment | E46: Payment evidence | F46: Record if method 37 is used | G46: Payment row | H46: Specified
A47: III | B47: III.37.amount | C47: Cash / bank debit: Amount | D47: Payment | E47: Payment evidence | F47: Record if method 37 is used | G47: Payment row | H47: Specified
A48: III | B48: III.38.bank | C48: Check: Drawee bank / agency | D48: Payment | E48: Payment evidence | F48: Record if method 38 is used | G48: Payment row | H48: Specified
A49: III | B49: III.38.number | C49: Check: Reference number | D49: Payment | E49: Payment evidence | F49: Record if method 38 is used | G49: Payment row | H49: Specified
A50: III | B50: III.38.date | C50: Check: Payment date | D50: Payment | E50: Payment evidence | F50: Record if method 38 is used | G50: Payment row | H50: Specified
A51: III | B51: III.38.amount | C51: Check: Amount | D51: Payment | E51: Payment evidence | F51: Record if method 38 is used | G51: Payment row | H51: Specified
A52: III | B52: III.39.bank | C52: Tax debit memo: Drawee bank / agency | D52: Payment | E52: Payment evidence | F52: Record if method 39 is used [No drawee key for item 39 in the pinned schema (txtNumber39, txtDate39, txtAmount39 only). Not fillable; row kept (correction 30).] | G52: Payment row | H52: Specified
A53: III | B53: III.39.number | C53: Tax debit memo: Reference number | D53: Payment | E53: Payment evidence | F53: Record if method 39 is used | G53: Payment row | H53: Specified
A54: III | B54: III.39.date | C54: Tax debit memo: Payment date | D54: Payment | E54: Payment evidence | F54: Record if method 39 is used | G54: Payment row | H54: Specified
... A84: III | B84: III.40.particular | C84: Other payment: particulars (txtParticular40) | D84: Payment | E84: Payment evidence | F84: Record if method 40 is used; unmapped in pinned schema | G84: Payment row | H84: Specified; added by correction 31

Sheet 1701-MS fields
A1: 1701-MS field dictionary
A2: August 2024, 2 pages. Field IDs include Part and item; each A/B field is separately scoped to taxpayer or spouse.
A3: All numbered fields are inventoried. Compensation uses the owner’s 2316, not the company’s 1601-C payroll. Official source S3.
A5: Section | B5: Field ID | C5: BIR field | D5: Origin | E5: Source / data | F5: Rule or condition | G5: Grain | H5: Status
A6: Header | B6: H.1 | C6: For the year (MM/YYYY) | D6: Period | E6: Tax year | F6: Annual | G6: Return | H6: Specified
A7: Header | B7: H.2 | C7: Amended return? | D7: Filing | E7: Return version | F7: Link original | G7: Return | H7: Specified
A8: Header | B8: H.3 | C8: Short period return? | D8: Filing | E8: Period metadata | F8: Yes/No | G8: Return | H8: Specified
A9: Header | B9: H.4 | C9: Civil status | D9: Person profile | E9: Taxpayer civil status | F9: Not a business category | G9: Return | H9: Specified
A10: Header | B10: H.5 | C10: If married, filing jointly / separately / spouse no income | D10: Person profile | E10: Filing election | F10: Confirm person-specific columns | G10: Return | H10: Specified
A11: I | B11: I.6 | C11: TIN | D11: Profile / election | E11: Taxpayer / spouse TIN | F11: Conditional; evaluate each taxpayer or spouse separately | G11: Person A / B | H11: Specified
A12: I | B12: I.7 | C12: RDO code | D12: Profile / election | E12: Person registration | F12: Conditional; evaluate each taxpayer or spouse separately | G12: Person A / B | H12: Specified
A13: I | B13: I.8 | C13: Name | D13: Profile / election | E13: Taxpayer / spouse name | F13: Conditional; evaluate each taxpayer or spouse separately | G13: Person A / B | H13: Specified
A14: I | B14: I.9 | C14: Email address | D14: Profile / election | E14: Person contact | F14: Conditional; evaluate each taxpayer or spouse separately | G14: Person A / B | H14: Specified
A15: I | B15: I.10 | C15: Contact number | D15: Profile / election | E15: Person contact | F15: Conditional; evaluate each taxpayer or spouse separately | G15: Person A / B | H15: Specified
A16: I | B16: I.11 | C16: Source of income | D16: Profile / election | E16: Business / profession / mixed / spouse compensation | F16: Conditional; evaluate each taxpayer or spouse separately | G16: Person A / B | H16: Specified
... A40: II | B40: II.32 | C40: Declaration / agreement | D40: Human | E40: Taxpayer consent | F40: Do not auto-sign | G40: Return | H40: Specified
A41: II | B41: II.33 (name, signature; unnumbered in schema) | C41: Name and signature of filer / representative | D41: Human | E41: Authorized signer | G41: Return | H41: Specified
A42: II | B42: II.34 | C42: TIN of authorized representative | D42: Profile | E42: Representative TIN | F42: Only when applicable No key exists for II.34 (TIN of authorized representative) in the pinned schema (verify s2 #14). | G42: Return | H42: Specified
A43: II | B43: II.33 | C43: Number of attachments (schema: 'Page 1 Item 33 Number Of Attachments', constant) (correction 32) | D43: Filing | E43: Attachment records | G43: Return | H43: Specified
A44: III | B44: III.36.bank | C44: Cash / bank debit: Drawee bank / agency | D44: Payment | E44: Payment evidence | F44: Record if method 36 is used | G44: Payment row | H44: Specified
A45: III | B45: III.36.number | C45: Cash / bank debit: Reference number | D45: Payment | E45: Payment evidence | F45: Record if method 36 is used | G45: Payment row | H45: Specified
A46: III | B46: III.36.date | C46: Cash / bank debit: Payment date | D46: Payment | E46: Payment evidence | F46: Record if method 36 is used | G46: Payment row | H46: Specified
A47: III | B47: III.36.amount | C47: Cash / bank debit: Amount | D47: Payment | E47: Payment evidence | F47: Record if method 36 is used | G47: Payment row | H47: Specified
A48: III | B48: III.37.bank | C48: Check: Drawee bank / agency | D48: Payment | E48: Payment evidence | F48: Record if method 37 is used | G48: Payment row | H48: Specified
A49: III | B49: III.37.number | C49: Check: Reference number | D49: Payment | E49: Payment evidence | F49: Record if method 37 is used | G49: Payment row | H49: Specified
A50: III | B50: III.37.date | C50: Check: Payment date | D50: Payment | E50: Payment evidence | F50: Record if method 37 is used | G50: Payment row | H50: Specified
A51: III | B51: III.37.amount | C51: Check: Amount | D51: Payment | E51: Payment evidence | F51: Record if method 37 is used | G51: Payment row | H51: Specified
A52: III | B52: III.38.bank | C52: Tax debit memo: Drawee bank / agency | D52: Payment | E52: Payment evidence | F52: Record if method 38 is used No tax-debit-memo drawee key in the pinned schema (number, date and amount only). Not fillable (correction 33). | G52: Payment row | H52: Specified
A53: III | B53: III.38.number | C53: Tax debit memo: Reference number | D53: Payment | E53: Payment evidence | F53: Record if method 38 is used | G53: Payment row | H53: Specified
A54: III | B54: III.38.date | C54: Tax debit memo: Payment date | D54: Payment | E54: Payment evidence | F54: Record if method 38 is used | G54: Payment row | H54: Specified
A55: III | B55: III.38.amount | C55: Tax debit memo: Amount | D55: Payment | E55: Payment evidence | F55: Record if method 38 is used | G55: Payment row | H55: Specified
... A66: IV | B66: IV.6 | C66: Sales returns, allowances and discounts | D66: Ledger + attributes | E66: refunds_and_discounts | F66: Linked to eligible sales; annual | G66: Person A / B | H66: Specified
A67: IV | B67: IV.7 | C67: Net sales / revenues / fees | D67: Calculated | E67: IV.5 - IV.6 | G67: Person A / B | H67: Specified
A68: IV | B68: IV.8 | C68: Cost of sales / services | D68: Ledger + tax review | E68: cost_of_goods_sold, direct service cost | F68: Itemized mode only | G68: Person A / B | H68: Specified
A69: IV | B69: IV.9 | C69: Gross income / loss from operation | D69: Calculated | E69: IV.7 - IV.8 | F69: IV.8 omitted for OSD | G69: Person A / B | H69: Specified
A70: IV | B70: IV.10A | C70: Ordinary allowable itemized deductions | D70: Ledger + tax review | E70: Eligible operating expenses and adjustments | F70: Only itemized; verify substantiation and limits | G70: Person A / B | H70: Specified
A71: IV | B71: IV.10B | C71: Special allowable itemized deductions | D71: Tax schedule | E71: Specific eligible special deductions | F71: Only itemized and supported | G71: Person A / B | H71: Specified
A72: IV | B72: IV.10C | C72: Net operating loss carryover | D72: Tax schedule | E72: Eligible loss vintages and utilization | F72: Eligibility and time limits | G72: Person A / B | H72: Specified
A73: IV | B73: IV.10D | C73: Total allowable itemized deductions | D73: Calculated | E73: IV.10A + IV.10B + IV.10C | F73: Do not mix with OSD | G73: Person A / B | H73: Specified
A74: IV | B74: IV.11 | C74: Optional standard deduction | D74: Calculated | E74: 40% of IV.7 | F74: Only when OSD validly elected | G74: Person A / B | H74: Specified
...

Sheet Worked example
A1: Worked example: selected form fields
A2: Fictional individual, graduated rates with OSD, Section 116 percentage tax, and one employee.
A3: Quarter 3 and September 2026; annual return covers all 2026 including a hypothetical Q4. Linked to Example data, not Profile.
A5: Form / field | B5: Field or step | C5: Amount / value | D5: Source / interpretation
A6: 2551Q S1.1.ATC | B6: Tax code | C6: PT010 | D6: Example assumption, Section 116
A7: 2551Q S1.1.base | B7: Q3 taxable sales | C7: =SUMIFS('Example data'!$F$6:$F$12,'Example data'!$B$6:$B$12,2026,'Example data'!$C$6:$C$12,3,'Example data'!$D$6:$D$12,"Sale",'Example data'!$G$6:$G$12,"PT010")-SUMIFS('Example data'!$F$6:$F$12,'Example data'!$B$6:$B$12,2026,'Example data'!$C$6:$C$12,3,'Example data'!$D$6:$D$12,"Return",'Example data'!$G$6:$G$12,"PT010") | D7: Q3 sale minus eligible return
A8: 2551Q S1.1.rate | B8: Percentage tax rate | C8: ='Example data'!B22 | D8: Example effective rate
A9: 2551Q S1.1.tax | B9: Percentage tax due | C9: =C7*C8 | D9: Base × rate
A10: 2551Q II.15 | B10: Percentage tax withheld | C10: ='Example data'!B21 | D10: Not the income-tax withholding on invoices
A11: 2551Q II.18 | B11: Total credits / payments (II.15 + II.16 + II.17; II.16 and II.17 are zero here) | C11: =C10+0+0 | D11: Only percentage-tax credit in this example; II.16 and II.17 are zero (correction 2)
A12: 2551Q II.19 | B12: Tax still payable (II.14 - II.18) | C12: =C9-C11 | D12: Tax due minus applicable credits (correction 1: was labelled II.24)
A14: 1601-C II.14 | B14: Total compensation | C14: ='Example data'!D17+'Example data'!E17 | D14: Basic gross plus exempt benefits
A15: 1601-C II.18 | B15: Exempt de minimis | C15: ='Example data'!E17 | D15: Employee payroll record
A16: 1601-C II.19 | B16: Employee mandatory contributions | C16: ='Example data'!F17 | D16: Employee share; employer share excluded
A17: 1601-C II.21 | B17: Total non-taxable compensation (II.15 to II.20) | C17: =0+0+0+C15+C16+0 | D17: II.15, II.16, II.17 and II.20 are zero here; II.18 = C15 and II.19 = C16 (correction 4)
A18: 1601-C II.22 | B18: Total taxable compensation | C18: =C14-C17 | D18: Gross less non-taxable
A19: 1601-C II.23 | B19: Taxable pay not subject to withholding | C19: ='Example data'!G17 | D19: Assumed zero for this employee
A20: 1601-C II.24 | B20: Net taxable compensation | C20: =C18-C19 | D20: II.22 less II.23
A21: 1601-C II.25 | B21: Income tax withheld | C21: ='Example data'!H17 | D21: From payroll; not recomputed here
A22: 1601-C II.26 | B22: Previous-month adjustment | C22: 0 | D22: Assumed zero
A23: 1601-C II.27 | B23: Taxes withheld for remittance | C23: =C21+C22 | D23: II.25 plus II.26
A24: 1601-C II.30 | B24: Prior / other remittances | C24: 0 | D24: Assumed zero
A25: 1601-C II.31 | B25: Tax still due / over-remittance (II.27 - II.30) | C25: =C23-C24 | D25: No penalties in this example (correction 3: was labelled II.36)
A27: 1701-MS IV.5 | B27: Annual sales | C27: =SUMIFS('Example data'!$F$6:$F$12,'Example data'!$B$6:$B$12,2026,'Example data'!$D$6:$D$12,"Sale") | D27: Sum annual sale entries
A28: 1701-MS IV.6 | B28: Annual returns / discounts | C28: =SUMIFS('Example data'!$F$6:$F$12,'Example data'!$B$6:$B$12,2026,'Example data'!$D$6:$D$12,"Return") | D28: Sum annual return entries
A29: 1701-MS IV.7 | B29: Net annual sales | C29: =C27-C28 | D29: IV.5 minus IV.6
A30: 1701-MS IV.11 | B30: Optional standard deduction | C30: =C29*'Example data'!B23 | D30: 40% of IV.7
A31: 1701-MS IV.13 | B31: Other non-operating income | C31: 0 | D31: Assumed zero
A32: 1701-MS IV.14 | B32: Taxable business income | C32: =C29-C30+C31 | D32: Net sales minus OSD plus other income
A33: 1701-MS IV.18B | B33: Graduated income tax due (applied to IV.15 = IV.3 + IV.14) | C33: =IF((C43+C32)<=250000,0,IF((C43+C32)<=400000,((C43+C32)-250000)*0.15,IF((C43+C32)<=800000,22500+((C43+C32)-400000)*0.2,IF((C43+C32)<=2000000,102500+((C43+C32)-800000)*0.25,IF((C43+C32)<=8000000,402500+((C43+C32)-2000000)*0.3,2202500+((C43+C32)-8000000)*0.35))))) | D33: Applied to IV.15 = IV.3 + IV.14; IV.3 is zero here (correction 5). Illustration: current progressive brackets
A34: 1701-MS V.2 | B34: Q1–Q3 tax payments | C34: ='Example data'!B20 | D34: Input supported by prior 1701Q payments
A35: 1701-MS V.3 | B35: Q1–Q3 income-tax withholding | C35: =SUMIFS('Example data'!$H$6:$H$12,'Example data'!$B$6:$B$12,2026,'Example data'!$C$6:$C$12,"<=3") | D35: Income-tax 2307s; three quarters
A36: 1701-MS V.4 | B36: Q4 income-tax withholding | C36: =SUMIFS('Example data'!$H$6:$H$12,'Example data'!$B$6:$B$12,2026,'Example data'!$C$6:$C$12,4) | D36: Income-tax 2307s; Q4
A37: 1701-MS V.10 | B37: Total credits / payments | C37: =SUM(C34:C36) | D37: Sum the three amounts above
A38: 1701-MS II.24 | B38: Total credits / payments | C38: =C37 | D38: From V.10
A39: 1701-MS II.25 | B39: Tax payable / overpayment (II.23 - II.24) | C39: =C44-C38 | D39: Equals II.27 and II.29 here: no second installment or penalties (correction 7). Chain in rows 43-46.
A40: 2551Q II.14 | B40: Total tax due (= Schedule 1 item 7) | C40: =C9 | D40: Added by correction 1.
A41: 2551Q II.24 | B41: Total amount payable (II.19 + II.23) | C41: =C12+0 | D41: Added by correction 1. II.23 (penalties) is zero here.
A42: 1601-C II.36 | B42: Amount still due (II.31 + II.35) | C42: =C25+0 | D42: Added by correction 3. II.35 (penalties) is zero here.
A43: 1701-MS IV.3 | B43: Taxable compensation (IV.1 - IV.2) | C43: 0 | D43: Added by correction 5. Zero in this example (no compensation).
...

Sheet Example data
A1: Fictional transactions and payroll
A2: These records feed the Worked example. All amounts are Philippine pesos; the annual Q4 transaction is hypothetical.
A3: Income-tax withholding on the sales is distinct from any percentage-tax withholding.
A5: Reference | B5: Year | C5: Quarter | D5: Type | E5: Category key | F5: Base amount | G5: PT ATC | H5: Income CWT | I5: Evidence
A6: INV-Q1 | B6: 2026 | C6: 1 | D6: Sale | E6: sales_revenue | F6: 300000 | G6: PT010 | H6: 3000 | I6: Invoice + income-tax 2307
A7: INV-Q2 | B7: 2026 | C7: 2 | D7: Sale | E7: sales_revenue | F7: 300000 | G7: PT010 | H7: 3000 | I7: Invoice + income-tax 2307
A8: INV-Q3 | B8: 2026 | C8: 3 | D8: Sale | E8: sales_revenue | F8: 300000 | G8: PT010 | H8: 2900 | I8: Invoice + income-tax 2307
A9: CN-Q3 | B9: 2026 | C9: 3 | D9: Return | E9: refunds_and_discounts | F9: 10000 | G9: PT010 | H9: 0 | I9: Credit note against Q3 sale
A10: INV-Q4 | B10: 2026 | C10: 4 | D10: Sale | E10: sales_revenue | F10: 300000 | G10: PT010 | H10: 3000 | I10: Invoice + income-tax 2307
A11: EXP-Q3 | B11: 2026 | C11: 3 | D11: Expense | E11: office_supplies | F11: 20000 | H11: 0 | I11: Supplier invoice
A12: PAY-SEP | B12: 2026 | C12: 3 | D12: Expense | E12: salaries | F12: 42000 | H12: 0 | I12: Gross employee payroll, September 2026 only (one month; July and August absent) (correction 10)
A15: One hypothetical employee, September 2026
A16: Employee | B16: Year | C16: Month | D16: Basic gross | E16: Exempt de minimis | F16: Employee contributions | G16: Below-threshold taxable pay | H16: Tax withheld
A17: E-001 | B17: 2026 | C17: 9 | D17: 40000 | E17: 2000 | F17: 2000 | G17: 0 | H17: 2808.4
A20: Q1–Q3 income-tax payments | B20: 40400
A21: Quarterly percentage tax withheld | B21: 0
A22: Section 116 percentage rate | B22: 0.03
A23: Individual OSD rate | B23: 0.4
A25: Data is for demonstrating field lineage. Prior payments and withholding are assumed supported; no statutory determination or payroll calculation is performed.
A26: Example assumes the tax periods, taxpayer eligibility, ATC, benefit exemptions, carryovers and prior payments have already been verified.

Sheet Form catalog
A1: Common form catalog
A2: Scope filtering is only a legal-entity screen; tax type, activity, elections and period still determine the actual filing.
A3: Only the three indicated forms have field dictionaries in this workbook; do not interpret “Not mapped” as no filing duty.
A5: Form | B5: Purpose | C5: Entity scope | D5: Typical trigger | E5: Frequency | F5: Coverage | G5: Entity screen | H5: Profile selection
A6: 1700 | B6: Annual compensation return | C6: Individual | D6: Employee must file; substitution rules may apply | E6: Annual | F6: Not mapped | G6: =IF(OR(C6="Any",AND(C6="Individual",Profile!$C$6="Individual"),AND(C6="Individual/Fiduciary",OR(Profile!$C$6="Individual",Profile!$C$6="Estate/Trust")),AND(C6="Non-individual",OR(Profile!$C$6="Corporation",Profile!$C$6="Partnership")),AND(C6="Estate/Trust",Profile!$C$6="Estate/Trust")),"In scope","Out of scope") | H6: ="Not selected here"
A7: 1701Q | B7: Quarterly individual income tax | C7: Individual/Fiduciary | D7: Business / professional income when required | E7: Q1–Q3 | F7: Not mapped | G7: =IF(OR(C7="Any",AND(C7="Individual",Profile!$C$6="Individual"),AND(C7="Individual/Fiduciary",OR(Profile!$C$6="Individual",Profile!$C$6="Estate/Trust")),AND(C7="Non-individual",OR(Profile!$C$6="Corporation",Profile!$C$6="Partnership")),AND(C7="Estate/Trust",Profile!$C$6="Estate/Trust")),"In scope","Out of scope") | H7: =IF(Profile!$G$6="Yes","Selected","Not selected")
A8: 1701 | B8: Annual individual income tax | C8: Individual/Fiduciary | D8: Business, mixed, multiple regimes and other applicable cases | E8: Annual | F8: Not mapped | G8: =IF(OR(C8="Any",AND(C8="Individual",Profile!$C$6="Individual"),AND(C8="Individual/Fiduciary",OR(Profile!$C$6="Individual",Profile!$C$6="Estate/Trust")),AND(C8="Non-individual",OR(Profile!$C$6="Corporation",Profile!$C$6="Partnership")),AND(C8="Estate/Trust",Profile!$C$6="Estate/Trust")),"In scope","Out of scope") | H8: =IF(Profile!$G$10="Yes","Selected","Not selected")
A9: 1701A | B9: Annual pure business income tax | C9: Individual | D9: Eligible pure business, 8% or graduated + OSD | E9: Annual | F9: Not mapped | G9: =IF(OR(C9="Any",AND(C9="Individual",Profile!$C$6="Individual"),AND(C9="Individual/Fiduciary",OR(Profile!$C$6="Individual",Profile!$C$6="Estate/Trust")),AND(C9="Non-individual",OR(Profile!$C$6="Corporation",Profile!$C$6="Partnership")),AND(C9="Estate/Trust",Profile!$C$6="Estate/Trust")),"In scope","Out of scope") | H9: =IF(Profile!$G$10="Yes","Selected","Not selected")
A10: 1701-MS | B10: Annual micro / small individual income tax | C10: Individual/Fiduciary | D10: Eligible micro/small individual; check form restrictions | E10: Annual | F10: Field dictionary | G10: =IF(OR(C10="Any",AND(C10="Individual",Profile!$C$6="Individual"),AND(C10="Individual/Fiduciary",OR(Profile!$C$6="Individual",Profile!$C$6="Estate/Trust")),AND(C10="Non-individual",OR(Profile!$C$6="Corporation",Profile!$C$6="Partnership")),AND(C10="Estate/Trust",Profile!$C$6="Estate/Trust")),"In scope","Out of scope") | H10: =IF(Profile!$C$9="Yes","Selected","Not selected")
A11: 1702Q | B11: Quarterly corporate income tax | C11: Non-individual | D11: Taxable corporation / partnership when required | E11: Q1–Q3 | F11: Not mapped | G11: =IF(OR(C11="Any",AND(C11="Individual",Profile!$C$6="Individual"),AND(C11="Individual/Fiduciary",OR(Profile!$C$6="Individual",Profile!$C$6="Estate/Trust")),AND(C11="Non-individual",OR(Profile!$C$6="Corporation",Profile!$C$6="Partnership")),AND(C11="Estate/Trust",Profile!$C$6="Estate/Trust")),"In scope","Out of scope") | H11: =IF(Profile!$G$7="Yes","Selected","Not selected")
A12: 1702-RT | B12: Regular-rate corporate annual | C12: Non-individual | D12: Regular-rate corporation / partnership | E12: Annual | F12: Not mapped | G12: =IF(OR(C12="Any",AND(C12="Individual",Profile!$C$6="Individual"),AND(C12="Individual/Fiduciary",OR(Profile!$C$6="Individual",Profile!$C$6="Estate/Trust")),AND(C12="Non-individual",OR(Profile!$C$6="Corporation",Profile!$C$6="Partnership")),AND(C12="Estate/Trust",Profile!$C$6="Estate/Trust")),"In scope","Out of scope") | H12: =IF(Profile!$G$7="Yes","Selected","Not selected")
A13: 1702-EX | B13: Exempt entity annual | C13: Non-individual | D13: Qualifying exempt entity with no other taxable income | E13: Annual | F13: Not mapped | G13: =IF(OR(C13="Any",AND(C13="Individual",Profile!$C$6="Individual"),AND(C13="Individual/Fiduciary",OR(Profile!$C$6="Individual",Profile!$C$6="Estate/Trust")),AND(C13="Non-individual",OR(Profile!$C$6="Corporation",Profile!$C$6="Partnership")),AND(C13="Estate/Trust",Profile!$C$6="Estate/Trust")),"In scope","Out of scope") | H13: =IF(Profile!$G$7="Yes","Selected","Not selected")
A14: 1702-MX | B14: Mixed / preferential corporate annual | C14: Non-individual | D14: Multiple / preferential income-tax rates | E14: Annual | F14: Not mapped | G14: =IF(OR(C14="Any",AND(C14="Individual",Profile!$C$6="Individual"),AND(C14="Individual/Fiduciary",OR(Profile!$C$6="Individual",Profile!$C$6="Estate/Trust")),AND(C14="Non-individual",OR(Profile!$C$6="Corporation",Profile!$C$6="Partnership")),AND(C14="Estate/Trust",Profile!$C$6="Estate/Trust")),"In scope","Out of scope") | H14: =IF(Profile!$G$7="Yes","Selected","Not selected")
A15: 2551Q | B15: Quarterly percentage tax | C15: Any | D15: Taxable business or sector; specific ATCs apply | E15: Quarterly | F15: Field dictionary | G15: =IF(OR(C15="Any",AND(C15="Individual",Profile!$C$6="Individual"),AND(C15="Individual/Fiduciary",OR(Profile!$C$6="Individual",Profile!$C$6="Estate/Trust")),AND(C15="Non-individual",OR(Profile!$C$6="Corporation",Profile!$C$6="Partnership")),AND(C15="Estate/Trust",Profile!$C$6="Estate/Trust")),"In scope","Out of scope") | H15: =IF(Profile!$C$7="Yes","Selected","Not selected")
A16: 2550Q | B16: Quarterly VAT | C16: Any | D16: VAT registration or applicable VAT liability | E16: Quarterly | F16: Not mapped | G16: =IF(OR(C16="Any",AND(C16="Individual",Profile!$C$6="Individual"),AND(C16="Individual/Fiduciary",OR(Profile!$C$6="Individual",Profile!$C$6="Estate/Trust")),AND(C16="Non-individual",OR(Profile!$C$6="Corporation",Profile!$C$6="Partnership")),AND(C16="Estate/Trust",Profile!$C$6="Estate/Trust")),"In scope","Out of scope") | H16: =IF(Profile!$G$8="Yes","Selected","Not selected")
